<?xml version="1.0"?>
<robot name="base_link">
    <link name="robot_base">
        <visual name="base_link">
            <origin rpy="-3.141593 3.141593 -3.141593" xyz="0.000000 0.000000 0.000000" />
            <geometry>
                <mesh filename="file://URDF/URDF4Pin/URDF4Pin_robot_base_vis_1.dae" />
            </geometry>
            <material name="robot_base_material">
                <color rgba="1.000000 1.000000 1.000000 1.0" />
            </material>
        </visual>
    </link>
    <joint name="Revolute_joint_01" type="revolute">
        <axis xyz="0 0 1" />
        <limit effort="0.52" upper="1.0471975511967" lower="-1.0471975511967" velocity="10.786134777326" />
        <parent link="robot_base" />
        <child link="coxa_1" />
        <origin rpy="-3.141593 3.141593 -3.141593" xyz="0.000000 -0.159208 0.059000" />
    </joint>
    <link name="coxa_1">
        <visual name="coxa_1">
            <origin rpy="-3.141593 3.141593 -3.141593" xyz="0.000000 0.159208 -0.059000" />
            <geometry>
                <mesh filename="file://URDF/URDF4Pin/URDF4Pin_coxa_1_vis_1.dae" />
            </geometry>
            <material name="coxa_1_material">
                <color rgba="1.000000 1.000000 1.000000 1.0" />
            </material>
        </visual>
    </link>
    <joint name="Revolute_joint_11" type="revolute">
        <axis xyz="0 0 1" />
        <limit effort="0.52" upper="1.0471975511967" lower="-1.0471975511967" velocity="10.786134777326" />
        <parent link="coxa_1" />
        <child link="femur_1" />
        <origin rpy="0.000000 1.570796 0.000000" xyz="0.000000 -0.047000 0.000000" />
    </joint>
    <link name="femur_1">
        <visual name="femur_1">
            <origin rpy="0.000000 -1.570796 0.000000" xyz="0.059000 0.206208 0.000000" />
            <geometry>
                <mesh filename="file://URDF/URDF4Pin/URDF4Pin_femur_1_vis_1.dae" />
            </geometry>
            <material name="femur_1_material">
                <color rgba="1.000000 1.000000 1.000000 1.0" />
            </material>
        </visual>
    </link>
    <joint name="Revolute_joint_21" type="revolute">
        <axis xyz="0 0 1" />
        <limit effort="0.52" upper="1.0471975511967" lower="-1.0471975511967" velocity="10.786134777326" />
        <parent link="femur_1" />
        <child link="tibia_1" />
        <origin rpy="-3.141593 3.141593 -3.141593" xyz="-0.038960 -0.023552 -0.000000" />
    </joint>
    <link name="tibia_1">
        <visual name="tibia_1">
            <origin rpy="0.000000 -1.570796 0.000000" xyz="0.097960 0.229760 0.000000" />
            <geometry>
                <mesh filename="file://URDF/URDF4Pin/URDF4Pin_tibia_1_vis_1.dae" />
            </geometry>
            <material name="tibia_1_material">
                <color rgba="1.000000 1.000000 1.000000 1.0" />
            </material>
        </visual>
    </link>
    <joint name="fixed_joint_31" type="fixed">
        <!-- <axis xyz="0 0 1" /> -->
        <parent link="tibia_1" />
        <child link="foot_1" />
        <origin rpy="0.000000 -1.570796 0.000000" xyz="0.097960 -0.020240 0.000000" />
    </joint>
    <link name="foot_1">
        <visual name="foot_1">
            <origin rpy="-3.141593 3.141593 -3.141593" xyz="0.000000 0.000000 0.000000" />
            <geometry>
                <sphere radius="0.0005" />
            </geometry>
            <material name="foot_1_material">
                <color rgba="0.850000 0.850000 1.000000 1.0" />
            </material>
        </visual>
    </link>
    <joint name="Revolute_joint_02" type="revolute">
        <axis xyz="0 0 1" />
        <limit effort="0.52" upper="1.0471975511967" lower="-1.0471975511967" velocity="10.786134777326" />
        <parent link="robot_base" />
        <child link="coxa_2" />
        <origin rpy="-3.141593 3.141593 1.047198" xyz="0.137878 -0.079604 0.059000" />
    </joint>
    <link name="coxa_2">
        <visual name="coxa_2">
            <origin rpy="-3.141593 3.141593 -1.047198" xyz="0.000000 -0.159208 -0.059000" />
            <geometry>
                <mesh filename="file://URDF/URDF4Pin/URDF4Pin_coxa_2_vis_1.dae" />
            </geometry>
            <material name="coxa_2_material">
                <color rgba="1.000000 1.000000 1.000000 1.0" />
            </material>
        </visual>
    </link>
    <joint name="Revolute_joint_12" type="revolute">
        <axis xyz="0 0 1" />
        <limit effort="0.52" upper="1.0471975511967" lower="-1.0471975511967" velocity="10.786134777326" />
        <parent link="coxa_2" />
        <child link="femur_2" />
        <origin rpy="0.000000 1.570796 0.000000" xyz="0.000000 0.047000 0.000000" />
    </joint>
    <link name="femur_2">
        <visual name="femur_2">
            <origin rpy="1.570796 2.617994 -1.570796" xyz="0.059000 -0.206208 0.000000" />
            <geometry>
                <mesh filename="file://URDF/URDF4Pin/URDF4Pin_femur_2_vis_1.dae" />
            </geometry>
            <material name="femur_2_material">
                <color rgba="1.000000 1.000000 1.000000 1.0" />
            </material>
        </visual>
    </link>
    <joint name="Revolute_joint_22" type="revolute">
        <axis xyz="0 0 1" />
        <limit effort="0.52" upper="1.0471975511967" lower="-1.0471975511967" velocity="10.786134777326" />
        <parent link="femur_2" />
        <child link="tibia_2" />
        <origin rpy="-3.141593 3.141593 -3.141593" xyz="-0.038960 0.023551 -0.000000" />
    </joint>
    <link name="tibia_2">
        <visual name="tibia_2">
            <origin rpy="1.570796 2.617994 -1.570796" xyz="0.097960 -0.229759 0.000000" />
            <geometry>
                <mesh filename="file://URDF/URDF4Pin/URDF4Pin_tibia_2_vis_1.dae" />
            </geometry>
            <material name="tibia_2_material">
                <color rgba="1.000000 1.000000 1.000000 1.0" />
            </material>
        </visual>
    </link>
    <joint name="fixed_joint_32" type="fixed">
        <!-- <axis xyz="0 0 1" /> -->
        <parent link="tibia_2" />
        <child link="foot_2" />
        <origin rpy="0.000000 -1.570796 0.000000" xyz="0.097960 0.020241 0.000000" />
    </joint>
    <link name="foot_2">
        <visual name="foot_2">
            <origin rpy="-3.141593 3.141593 -3.141593" xyz="0.000000 0.000000 0.000000" />
            <geometry>
                <sphere radius="0.0005" />
            </geometry>
            <material name="foot_2_material">
                <color rgba="0.850000 0.850000 1.000000 1.0" />
            </material>
        </visual>
    </link>
    <joint name="Revolute_joint_03" type="revolute">
        <axis xyz="0 0 1" />
        <limit effort="0.52" upper="1.0471975511967" lower="-1.0471975511967" velocity="10.786134777326" />
        <parent link="robot_base" />
        <child link="coxa_3" />
        <origin rpy="-3.141593 3.141593 2.094395" xyz="0.137878 0.079604 0.059000" />
    </joint>
    <link name="coxa_3">
        <visual name="coxa_3">
            <origin rpy="-3.141593 3.141593 -2.094395" xyz="0.000000 -0.159208 -0.059000" />
            <geometry>
                <mesh filename="file://URDF/URDF4Pin/URDF4Pin_coxa_3_vis_1.dae" />
            </geometry>
            <material name="coxa_3_material">
                <color rgba="1.000000 1.000000 1.000000 1.0" />
            </material>
        </visual>
    </link>
    <joint name="Revolute_joint_13" type="revolute">
        <axis xyz="0 0 1" />
        <limit effort="0.52" upper="1.0471975511967" lower="-1.0471975511967" velocity="10.786134777326" />
        <parent link="coxa_3" />
        <child link="femur_3" />
        <origin rpy="0.000000 1.570796 0.000000" xyz="-0.000000 0.047002 0.000000" />
    </joint>
    <link name="femur_3">
        <visual name="femur_3">
            <origin rpy="1.570796 3.665191 -1.570796" xyz="0.059000 -0.206210 0.000000" />
            <geometry>
                <mesh filename="file://URDF/URDF4Pin/URDF4Pin_femur_3_vis_1.dae" />
            </geometry>
            <material name="femur_3_material">
                <color rgba="1.000000 1.000000 1.000000 1.0" />
            </material>
        </visual>
    </link>
    <joint name="Revolute_joint_23" type="revolute">
        <axis xyz="0 0 1" />
        <limit effort="0.52" upper="1.0471975511967" lower="-1.0471975511967" velocity="10.786134777326" />
        <parent link="femur_3" />
        <child link="tibia_3" />
        <origin rpy="-3.141593 3.141593 -3.141593" xyz="-0.038960 0.023550 -0.000000" />
    </joint>
    <link name="tibia_3">
        <visual name="tibia_3">
            <origin rpy="1.570796 3.665191 -1.570796" xyz="0.097960 -0.229760 0.000000" />
            <geometry>
                <mesh filename="file://URDF/URDF4Pin/URDF4Pin_tibia_3_vis_1.dae" />
            </geometry>
            <material name="tibia_3_material">
                <color rgba="1.000000 1.000000 1.000000 1.0" />
            </material>
        </visual>
    </link>
    <joint name="fixed_joint_33" type="fixed">
        <!-- <axis xyz="0 0 1" /> -->
        <parent link="tibia_3" />
        <child link="foot_3" />
        <origin rpy="0.000000 -1.570796 0.000000" xyz="0.097960 0.020240 0.000000" />
    </joint>
    <link name="foot_3">
        <visual name="foot_3">
            <origin rpy="-3.141593 3.141593 -3.141593" xyz="0.000000 0.000000 0.000000" />
            <geometry>
                <sphere radius="0.0005" />
            </geometry>
            <material name="foot_3_material">
                <color rgba="0.850000 0.850000 1.000000 1.0" />
            </material>
        </visual>
    </link>
    <joint name="Revolute_joint_04" type="revolute">
        <axis xyz="0 0 1" />
        <limit effort="0.52" upper="1.0471975511967" lower="-1.0471975511967" velocity="10.786134777326" />
        <parent link="robot_base" />
        <child link="coxa_4" />
        <origin rpy="-3.141593 3.141593 -3.141593" xyz="0.000000 0.159208 0.059000" />
    </joint>
    <link name="coxa_4">
        <visual name="coxa_4">
            <origin rpy="-3.141593 3.141593 -3.141593" xyz="0.000000 -0.159208 -0.059000" />
            <geometry>
                <mesh filename="file://URDF/URDF4Pin/URDF4Pin_coxa_4_vis_1.dae" />
            </geometry>
            <material name="coxa_4_material">
                <color rgba="1.000000 1.000000 1.000000 1.0" />
            </material>
        </visual>
    </link>
    <joint name="Revolute_joint_14" type="revolute">
        <axis xyz="0 0 1" />
        <limit effort="0.52" upper="1.0471975511967" lower="-1.0471975511967" velocity="10.786134777326" />
        <parent link="coxa_4" />
        <child link="femur_4" />
        <origin rpy="0.000000 1.570796 0.000000" xyz="0.000000 0.047000 0.000000" />
    </joint>
    <link name="femur_4">
        <visual name="femur_4">
            <origin rpy="0.000000 -1.570796 0.000000" xyz="0.059000 -0.206208 0.000000" />
            <geometry>
                <mesh filename="file://URDF/URDF4Pin/URDF4Pin_femur_4_vis_1.dae" />
            </geometry>
            <material name="femur_4_material">
                <color rgba="1.000000 1.000000 1.000000 1.0" />
            </material>
        </visual>
    </link>
    <joint name="Revolute_joint_24" type="revolute">
        <axis xyz="0 0 1" />
        <limit effort="0.52" upper="1.0471975511967" lower="-1.0471975511967" velocity="10.786134777326" />
        <parent link="femur_4" />
        <child link="tibia_4" />
        <origin rpy="-3.141593 3.141593 -3.141593" xyz="-0.038960 0.023552 -0.000000" />
    </joint>
    <link name="tibia_4">
        <visual name="tibia_4">
            <origin rpy="0.000000 -1.570796 0.000000" xyz="0.097960 -0.229760 0.000000" />
            <geometry>
                <mesh filename="file://URDF/URDF4Pin/URDF4Pin_tibia_4_vis_1.dae" />
            </geometry>
            <material name="tibia_4_material">
                <color rgba="1.000000 1.000000 1.000000 1.0" />
            </material>
        </visual>
    </link>
    <joint name="fixed_joint_34" type="fixed">
        <!-- <axis xyz="0 0 1" /> -->
        <parent link="tibia_4" />
        <child link="foot_4" />
        <origin rpy="0.000000 -1.570796 0.000000" xyz="0.097960 0.020240 0.000000" />
    </joint>
    <link name="foot_4">
        <visual name="foot_4">
            <origin rpy="-3.141593 3.141593 -3.141593" xyz="0.000000 0.000000 0.000000" />
            <geometry>
                <sphere radius="0.0005" />
            </geometry>
            <material name="foot_4_material">
                <color rgba="1.000000 0.000000 0.000000 1.0" />
            </material>
        </visual>
    </link>
    <joint name="Revolute_joint_05" type="revolute">
        <axis xyz="0 0 1" />
        <limit effort="0.52" upper="1.0471975511967" lower="-1.0471975511967" velocity="10.786134777326" />
        <parent link="robot_base" />
        <child link="coxa_5" />
        <origin rpy="-3.141593 3.141593 -2.094395" xyz="-0.137878 0.079604 0.059000" />
    </joint>
    <link name="coxa_5">
        <visual name="coxa_5">
            <origin rpy="-3.141593 3.141593 2.094395" xyz="0.000000 -0.159208 -0.059000" />
            <geometry>
                <mesh filename="file://URDF/URDF4Pin/URDF4Pin_coxa_5_vis_1.dae" />
            </geometry>
            <material name="coxa_5_material">
                <color rgba="1.000000 1.000000 1.000000 1.0" />
            </material>
        </visual>
    </link>
    <joint name="Revolute_joint_15" type="revolute">
        <axis xyz="0 0 1" />
        <limit effort="0.52" upper="1.0471975511967" lower="-1.0471975511967" velocity="10.786134777326" />
        <parent link="coxa_5" />
        <child link="femur_5" />
        <origin rpy="0.000000 1.570796 0.000000" xyz="0.000000 0.047000 0.000000" />
    </joint>
    <link name="femur_5">
        <visual name="femur_5">
            <origin rpy="-1.570796 3.665191 1.570796" xyz="0.059000 -0.206208 0.000000" />
            <geometry>
                <mesh filename="file://URDF/URDF4Pin/URDF4Pin_femur_5_vis_1.dae" />
            </geometry>
            <material name="femur_5_material">
                <color rgba="1.000000 1.000000 1.000000 1.0" />
            </material>
        </visual>
    </link>
    <joint name="Revolute_joint_25" type="revolute">
        <axis xyz="0 0 1" />
        <limit effort="0.52" upper="1.0471975511967" lower="-1.0471975511967" velocity="10.786134777326" />
        <parent link="femur_5" />
        <child link="tibia_5" />
        <origin rpy="-3.141593 3.141593 -3.141593" xyz="-0.038960 0.023552 -0.000000" />
    </joint>
    <link name="tibia_5">
        <visual name="tibia_5">
            <origin rpy="-1.570796 3.665191 1.570796" xyz="0.097960 -0.229760 0.000000" />
            <geometry>
                <mesh filename="file://URDF/URDF4Pin/URDF4Pin_tibia_5_vis_1.dae" />
            </geometry>
            <material name="tibia_5_material">
                <color rgba="1.000000 1.000000 1.000000 1.0" />
            </material>
        </visual>
    </link>
    <joint name="fixed_joint_35" type="fixed">
        <!-- <axis xyz="0 0 1" /> -->
        <parent link="tibia_5" />
        <child link="foot_5" />
        <origin rpy="0.000000 -1.570796 0.000000" xyz="0.097960 0.020240 0.000000" />
    </joint>
    <link name="foot_5">
        <visual name="foot_5">
            <origin rpy="-3.141593 3.141593 -3.141593" xyz="0.000000 0.000000 0.000000" />
            <geometry>
                <sphere radius="0.0005" />
            </geometry>
            <material name="foot_5_material">
                <color rgba="0.850000 0.850000 1.000000 1.0" />
            </material>
        </visual>
    </link>
    <joint name="Revolute_joint_06" type="revolute">
        <axis xyz="0 0 1" />
        <limit effort="0.52" upper="1.0471975511967" lower="-1.0471975511967" velocity="10.786134777326" />
        <parent link="robot_base" />
        <child link="coxa_6" />
        <origin rpy="-3.141593 3.141593 -1.047198" xyz="-0.137871 -0.079600 0.059000" />
    </joint>
    <link name="coxa_6">
        <visual name="coxa_6">
            <origin rpy="-3.141593 3.141593 1.047198" xyz="0.000000 -0.159200 -0.059000" />
            <geometry>
                <mesh filename="file://URDF/URDF4Pin/URDF4Pin_coxa_6_vis_1.dae" />
            </geometry>
            <material name="coxa_6_material">
                <color rgba="1.000000 1.000000 1.000000 1.0" />
            </material>
        </visual>
    </link>
    <joint name="Revolute_joint_16" type="revolute">
        <axis xyz="0 0 1" />
        <limit effort="0.52" upper="1.0471975511967" lower="-1.0471975511967" velocity="10.786134777326" />
        <parent link="coxa_6" />
        <child link="femur_6" />
        <origin rpy="0.000000 1.570796 0.000000" xyz="0.000000 0.047008 0.000000" />
    </joint>
    <link name="femur_6">
        <visual name="femur_6">
            <origin rpy="-1.570796 2.617994 1.570796" xyz="0.059000 -0.206208 0.000000" />
            <geometry>
                <mesh filename="file://URDF/URDF4Pin/URDF4Pin_femur_6_vis_1.dae" />
            </geometry>
            <material name="femur_6_material">
                <color rgba="1.000000 1.000000 1.000000 1.0" />
            </material>
        </visual>
    </link>
    <joint name="Revolute_joint_26" type="revolute">
        <axis xyz="0 0 1" />
        <limit effort="0.52" upper="1.0471975511967" lower="-1.0471975511967" velocity="10.786134777326" />
        <parent link="femur_6" />
        <child link="tibia_6" />
        <origin rpy="-3.141593 3.141593 -3.141593" xyz="-0.038960 0.023552 -0.000000" />
    </joint>
    <link name="tibia_6">
        <visual name="tibia_6">
            <origin rpy="-1.570796 2.617994 1.570796" xyz="0.097960 -0.229760 0.000000" />
            <geometry>
                <mesh filename="file://URDF/URDF4Pin/URDF4Pin_tibia_6_vis_1.dae" />
            </geometry>
            <material name="tibia_6_material">
                <color rgba="1.000000 1.000000 1.000000 1.0" />
            </material>
        </visual>
    </link>
    <joint name="fixed_joint_36" type="fixed">
        <!-- <axis xyz="0 0 1" /> -->
        <parent link="tibia_6" />
        <child link="foot_6" />
        <origin rpy="0.000000 -1.570796 0.000000" xyz="0.097960 0.020240 0.000000" />
    </joint>
    <link name="foot_6">
        <visual name="foot_6">
            <origin rpy="-3.141593 3.141593 -3.141593" xyz="0.000000 0.000000 0.000000" />
            <geometry>
                <sphere radius="0.0005" />
            </geometry>
            <material name="foot_6_material">
                <color rgba="0.850000 0.850000 1.000000 1.0" />
            </material>
        </visual>
    </link>
</robot>
