<?xml version="1.0"?>
<robot name="robot_base_visual">
    <link name="robot_base">
        <visual name="robot_base_visual">
            <origin xyz="-0.000000 -0.000000 -0.000000" rpy="-3.141593 3.141593 -3.141593" />
            <geometry>
                <mesh filename="file:///media/shantanu/Shantanu/hexapod/meshcat_sim/re2/IKTRials_redone naming convention_robot_base_vis_1.dae" />
            </geometry>
            <material name="robot_base_material">
                <color rgba="1.000000 1.000000 1.000000 1.0" />
            </material>
        </visual>
    </link>
    <joint type="continuous" name="Revolute_joint_01">
        <axis xyz="0 0 1" />
        <parent link="robot_base" />
        <child link="Coxa_1_visual" />
        <origin xyz="-0.000000 -0.800000 0.415000" rpy="3.141592 3.141593 1.570796" />
    </joint>
    <link name="Coxa_1_visual">
        <visual name="Coxa_1_visual">
            <origin xyz="-0.800000 -0.000000 -0.415000" rpy="-3.141592 3.141593 -1.570796" />
            <geometry>
                <mesh filename="file:///media/shantanu/Shantanu/hexapod/meshcat_sim/re2/IKTRials_redone naming convention_Coxa_1_visual_vis_1.dae" />
            </geometry>
            <material name="Coxa_1_visual_material">
                <color rgba="1.000000 1.000000 1.000000 1.0" />
            </material>
        </visual>
    </link>
    <joint type="continuous" name="Revolute_joint_11">
        <axis xyz="0 0 1" />
        <parent link="Coxa_1_visual" />
        <child link="Femur_1_visual" />
        <origin xyz="0.234000 0.000000 -0.007500" rpy="-1.570796 3.539528 -3.141592" />
    </joint>
    <link name="Femur_1_visual">
        <visual name="Femur_1_visual">
            <origin xyz="-1.111119 0.025033 -0.000000" rpy="-1.172861 1.570796 0.000000" />
            <geometry>
                <mesh filename="file:///media/shantanu/Shantanu/hexapod/meshcat_sim/re2/IKTRials_redone naming convention_Femur_1_visual_vis_1.dae" />
            </geometry>
            <material name="Femur_1_visual_material">
                <color rgba="1.000000 1.000000 1.000000 1.0" />
            </material>
        </visual>
    </link>
    <joint type="continuous" name="Revolute_joint_21">
        <axis xyz="0 0 1" />
        <parent link="Femur_1_visual" />
        <child link="Tibia_1_visual" />
        <origin xyz="0.228211 -0.000017 -0.000000" rpy="3.141593 3.141593 1.413717" />
    </joint>
    <link name="Tibia_1_visual">
        <visual name="Tibia_1_visual">
            <origin xyz="0.184776 -1.326759 -0.000000" rpy="-2.900736 1.570796 0.000000" />
            <geometry>
                <mesh filename="file:///media/shantanu/Shantanu/hexapod/meshcat_sim/re2/IKTRials_redone naming convention_Tibia_1_visual_vis_1.dae" />
            </geometry>
            <material name="Tibia_1_visual_material">
                <color rgba="1.000000 1.000000 1.000000 1.0" />
            </material>
        </visual>
        <visual name="Foot_1">
            <origin xyz="0.510733 0.000295 0.001500" rpy="-2.900736 1.570796 0.000000" />
            <geometry>
                <sphere radius="0.005" />
            </geometry>
            <material name="Foot_1_material">
                <color rgba="0.850000 0.850000 1.000000 1.0" />
            </material>
        </visual>
    </link>
    <joint type="continuous" name="Revolute_joint_02">
        <axis xyz="0 0 1" />
        <parent link="robot_base" />
        <child link="Coxa_2_visual" />
        <origin xyz="-0.690000 -0.398000 0.415000" rpy="3.141592 3.141593 0.523599" />
    </joint>
    <link name="Coxa_2_visual">
        <visual name="Coxa_2_visual">
            <origin xyz="-0.796558 0.000322 -0.415000" rpy="3.141593 3.141593 -0.523599" />
            <geometry>
                <mesh filename="file:///media/shantanu/Shantanu/hexapod/meshcat_sim/re2/IKTRials_redone naming convention_Coxa_2_visual_vis_1.dae" />
            </geometry>
            <material name="Coxa_2_visual_material">
                <color rgba="1.000000 1.000000 1.000000 1.0" />
            </material>
        </visual>
    </link>
    <joint type="continuous" name="Revolute_joint_12">
        <axis xyz="0 0 1" />
        <parent link="Coxa_2_visual" />
        <child link="Femur_2_visual" />
        <origin xyz="0.234839 0.008753 -0.007500" rpy="-1.570796 3.539528 3.141592" />
    </joint>
    <link name="Femur_2_visual">
        <visual name="Femur_2_visual">
            <origin xyz="-1.108719 0.024024 0.008431" rpy="-1.570796 2.617994 -0.397936" />
            <geometry>
                <mesh filename="file:///media/shantanu/Shantanu/hexapod/meshcat_sim/re2/IKTRials_redone naming convention_Femur_2_visual_vis_1.dae" />
            </geometry>
            <material name="Femur_2_visual_material">
                <color rgba="1.000000 1.000000 1.000000 1.0" />
            </material>
        </visual>
    </link>
    <joint type="continuous" name="Revolute_joint_22">
        <axis xyz="0 0 1" />
        <parent link="Femur_2_visual" />
        <child link="Tibia_2_visual" />
        <origin xyz="0.227337 -0.000287 0.005997" rpy="3.141592 3.141593 1.413717" />
    </joint>
    <link name="Tibia_2_visual">
        <visual name="Tibia_2_visual">
            <origin xyz="0.184994 -1.323410 0.002434" rpy="-1.570797 2.617994 1.329940" />
            <geometry>
                <mesh filename="file:///media/shantanu/Shantanu/hexapod/meshcat_sim/re2/IKTRials_redone naming convention_Tibia_2_visual_vis_1.dae" />
            </geometry>
            <material name="Tibia_2_visual_material">
                <color rgba="1.000000 1.000000 1.000000 1.0" />
            </material>
        </visual>
    </link>
    <joint type="continuous" name="Revolute_joint_03">
        <axis xyz="0 0 1" />
        <parent link="robot_base" />
        <child link="Coxa_3_visual" />
        <origin xyz="-0.690000 0.398000 0.415000" rpy="-3.141592 3.141593 -0.523599" />
    </joint>
    <link name="Coxa_3_visual">
        <visual name="Coxa_3_visual">
            <origin xyz="-0.796558 -0.000322 -0.415000" rpy="-3.141593 3.141593 0.523599" />
            <geometry>
                <mesh filename="file:///media/shantanu/Shantanu/hexapod/meshcat_sim/re2/IKTRials_redone naming convention_Coxa_3_visual_vis_1.dae" />
            </geometry>
            <material name="Coxa_3_visual_material">
                <color rgba="1.000000 1.000000 1.000000 1.0" />
            </material>
        </visual>
    </link>
    <joint type="continuous" name="Revolute_joint_13">
        <axis xyz="0 0 1" />
        <parent link="Coxa_3_visual" />
        <child link="Femur_3_visual" />
        <origin xyz="0.234000 -0.005000 -0.007500" rpy="-1.570796 3.539528 3.141592" />
    </joint>
    <link name="Femur_3_visual">
        <visual name="Femur_3_visual">
            <origin xyz="-1.107946 0.023698 -0.004677" rpy="-1.570796 3.665192 -0.397936" />
            <geometry>
                <mesh filename="file:///media/shantanu/Shantanu/hexapod/meshcat_sim/re2/IKTRials_redone naming convention_Femur_3_visual_vis_1.dae" />
            </geometry>
            <material name="Femur_3_visual_material">
                <color rgba="1.000000 1.000000 1.000000 1.0" />
            </material>
        </visual>
    </link>
    <joint type="continuous" name="Revolute_joint_23">
        <axis xyz="0 0 1" />
        <parent link="Femur_3_visual" />
        <child link="Tibia_3_visual" />
        <origin xyz="0.228689 0.000131 -0.003000" rpy="3.141592 3.141593 1.413717" />
    </joint>
    <link name="Tibia_3_visual">
        <visual name="Tibia_3_visual">
            <origin xyz="0.185818 -1.323865 -0.001678" rpy="-1.570796 3.665192 1.329940" />
            <geometry>
                <mesh filename="file:///media/shantanu/Shantanu/hexapod/meshcat_sim/re2/IKTRials_redone naming convention_Tibia_3_visual_vis_1.dae" />
            </geometry>
            <material name="Tibia_3_visual_material">
                <color rgba="1.000000 1.000000 1.000000 1.0" />
            </material>
        </visual>
    </link>
    <joint type="continuous" name="Revolute_joint_04">
        <axis xyz="0 0 1" />
        <parent link="robot_base" />
        <child link="Coxa_4_visual" />
        <origin xyz="0.000000 0.800000 0.415000" rpy="-3.141592 3.141593 -1.570796" />
    </joint>
    <link name="Coxa_4_visual">
        <visual name="Coxa_4_visual">
            <origin xyz="-0.800000 0.000000 -0.415000" rpy="3.141592 3.141593 1.570796" />
            <geometry>
                <mesh filename="file:///media/shantanu/Shantanu/hexapod/meshcat_sim/re2/IKTRials_redone naming convention_Coxa_4_visual_vis_1.dae" />
            </geometry>
            <material name="Coxa_4_visual_material">
                <color rgba="1.000000 1.000000 1.000000 1.0" />
            </material>
        </visual>
    </link>
    <joint type="continuous" name="Revolute_joint_14">
        <axis xyz="0 0 1" />
        <parent link="Coxa_4_visual" />
        <child link="Femur_4_visual" />
        <origin xyz="0.231500 -0.001000 -0.007500" rpy="-1.570797 3.469715 -3.141593" />
    </joint>
    <link name="Femur_4_visual">
        <visual name="Femur_4_visual">
            <origin xyz="-1.107792 -0.053342 -0.001000" rpy="-1.898919 -1.570796 0.000000" />
            <geometry>
                <mesh filename="file:///media/shantanu/Shantanu/hexapod/meshcat_sim/re2/IKTRials_redone naming convention_Femur_4_visual_vis_1.dae" />
            </geometry>
            <material name="Femur_4_visual_material">
                <color rgba="1.000000 1.000000 1.000000 1.0" />
            </material>
        </visual>
    </link>
    <joint type="continuous" name="Revolute_joint_24">
        <axis xyz="0 0 1" />
        <parent link="Femur_4_visual" />
        <child link="Tibia_4_visual" />
        <origin xyz="0.226300 -0.000608 -0.001000" rpy="-3.141593 3.141592 1.413717" />
    </joint>
    <link name="Tibia_4_visual">
        <visual name="Tibia_4_visual">
            <origin xyz="0.260782 -1.309418 -0.000000" rpy="-0.171043 -1.570796 0.000000" />
            <geometry>
                <mesh filename="file:///media/shantanu/Shantanu/hexapod/meshcat_sim/re2/IKTRials_redone naming convention_Tibia_4_visual_vis_1.dae" />
            </geometry>
            <material name="Tibia_4_visual_material">
                <color rgba="1.000000 1.000000 1.000000 1.0" />
            </material>
        </visual>
    </link>
    <joint type="continuous" name="Revolute_joint_05">
        <axis xyz="0 0 1" />
        <parent link="robot_base" />
        <child link="Coxa_5_visual" />
        <origin xyz="0.690000 0.400000 0.415000" rpy="3.141592 3.141593 -2.617994" />
    </joint>
    <link name="Coxa_5_visual">
        <visual name="Coxa_5_visual">
            <origin xyz="-0.797558 -0.001410 -0.415000" rpy="-3.141593 3.141592 2.617994" />
            <geometry>
                <mesh filename="file:///media/shantanu/Shantanu/hexapod/meshcat_sim/re2/IKTRials_redone naming convention_Coxa_5_visual_vis_1.dae" />
            </geometry>
            <material name="Coxa_5_visual_material">
                <color rgba="1.000000 1.000000 1.000000 1.0" />
            </material>
        </visual>
    </link>
    <joint type="continuous" name="Revolute_joint_15">
        <axis xyz="0 0 1" />
        <parent link="Coxa_5_visual" />
        <child link="Femur_5_visual" />
        <origin xyz="0.233808 -0.002096 -0.007000" rpy="-1.570796 3.539528 -3.141592" />
    </joint>
    <link name="Femur_5_visual">
        <visual name="Femur_5_visual">
            <origin xyz="-1.108884 0.023551 -0.000686" rpy="1.570796 3.665192 2.743657" />
            <geometry>
                <mesh filename="file:///media/shantanu/Shantanu/hexapod/meshcat_sim/re2/IKTRials_redone naming convention_Femur_5_visual_vis_1.dae" />
            </geometry>
            <material name="Femur_5_visual_material">
                <color rgba="1.000000 1.000000 1.000000 1.0" />
            </material>
        </visual>
    </link>
    <joint type="continuous" name="Revolute_joint_25">
        <axis xyz="0 0 1" />
        <parent link="Femur_5_visual" />
        <child link="Tibia_5_visual" />
        <origin xyz="0.227304 0.000226 -0.005253" rpy="3.141592 3.141593 1.413717" />
    </joint>
    <link name="Tibia_5_visual">
        <visual name="Tibia_5_visual">
            <origin xyz="0.185988 -1.323386 0.004566" rpy="1.570797 3.665192 -1.811653" />
            <geometry>
                <mesh filename="file:///media/shantanu/Shantanu/hexapod/meshcat_sim/re2/IKTRials_redone naming convention_Tibia_5_visual_vis_1.dae" />
            </geometry>
            <material name="Tibia_5_visual_material">
                <color rgba="1.000000 1.000000 1.000000 1.0" />
            </material>
        </visual>
    </link>
    <joint type="continuous" name="Revolute_joint_06">
        <axis xyz="0 0 1" />
        <parent link="robot_base" />
        <child link="Coxa_6_visual" />
        <origin xyz="0.690000 -0.400000 0.415000" rpy="3.141592 3.141593 2.617994" />
    </joint>
    <link name="Coxa_6_visual">
        <visual name="Coxa_6_visual">
            <origin xyz="-0.797558 0.001410 -0.415000" rpy="-3.141592 3.141593 -2.617994" />
            <geometry>
                <mesh filename="file:///media/shantanu/Shantanu/hexapod/meshcat_sim/re2/IKTRials_redone naming convention_Coxa_6_visual_vis_1.dae" />
            </geometry>
            <material name="Coxa_6_visual_material">
                <color rgba="1.000000 1.000000 1.000000 1.0" />
            </material>
        </visual>
    </link>
    <joint type="continuous" name="Revolute_joint_16">
        <axis xyz="0 0 1" />
        <parent link="Coxa_6_visual" />
        <child link="Femur_6_visual" />
        <origin xyz="0.234500 -0.000500 -0.007500" rpy="-1.570796 3.469715 -3.141592" />
    </joint>
    <link name="Femur_6_visual">
        <visual name="Femur_6_visual">
            <origin xyz="-1.108320 -0.053162 -0.001911" rpy="1.570796 2.617994 2.813470" />
            <geometry>
                <mesh filename="file:///media/shantanu/Shantanu/hexapod/meshcat_sim/re2/IKTRials_redone naming convention_Femur_6_visual_vis_1.dae" />
            </geometry>
            <material name="Femur_6_visual_material">
                <color rgba="1.000000 1.000000 1.000000 1.0" />
            </material>
        </visual>
    </link>
    <joint type="revolute" name="Revolute_joint_26">
        <axis xyz="0 0 1" />
        <limit velocity="0.18825295844937" effort="0.52" upper="1.0471975511967" lower="-1.0471975511967" />
        <parent link="Femur_6_visual" />
        <child link="Tibia_6_visual" />
        <origin xyz="0.227551 -0.001268 -0.004000" rpy="3.141592 3.141593 1.413717" />
    </joint>
    <link name="Tibia_6_visual">
        <visual name="Tibia_6_visual">
            <origin xyz="0.260231 -1.311306 0.002089" rpy="1.570797 2.617995 -1.741839" />
            <geometry>
                <mesh filename="file:///media/shantanu/Shantanu/hexapod/meshcat_sim/re2/IKTRials_redone naming convention_Tibia_6_visual_vis_1.dae" />
            </geometry>
            <material name="Tibia_6_visual_material">
                <color rgba="1.000000 1.000000 1.000000 1.0" />
            </material>
        </visual>
    </link>
</robot>
