<?xml version="1.0"?>
<robot name="base_link">
    <link name="robot_base">
        <visual name="base_link">
            <origin xyz="0.000000 0.000000 0.315000" rpy="-3.141593 3.141593 -3.141593" />
            <geometry>
                <mesh filename="file:///media/shantanu/Shantanu/hexapod/meshcat_sim/re/IKTRials_redone naming convention_robot_base_vis_1.dae" />
            </geometry>
            <material name="robot_base_material">
                <color rgba="1.000000 1.000000 1.000000 1.0" />
            </material>
        </visual>
    </link>
    <joint name="Revolute_joint_01" type="continuous">
        <axis xyz="0 0 1" />
        <parent link="robot_base" />
        <child link="Coxa_1" />
        <origin xyz="0.000000 -0.800000 0.415000" rpy="-3.141593 3.141593 1.570796" />
    </joint>
    <link name="Coxa_1">
        <visual name="Coxa_1">
            <origin xyz="-0.797000 0.000000 -0.100000" rpy="3.141593 3.141593 -1.570796" />
            <geometry>
                <mesh filename="file:///media/shantanu/Shantanu/hexapod/meshcat_sim/re/IKTRials_redone naming convention_Coxa_1_vis_1.dae" />
            </geometry>
            <material name="Coxa_1_material">
                <color rgba="1.000000 1.000000 1.000000 1.0" />
            </material>
        </visual>
    </link>
    <joint name="Revolute_joint_11" type="continuous">
        <axis xyz="0 0 1" />
        <parent link="Coxa_1" />
        <child link="Femur_1" />
        <origin xyz="0.234000 -0.000000 -0.007500" rpy="-1.570796 3.539528 3.141593" />
    </joint>
    <link name="Femur_1">
        <visual name="Femur_1">
            <origin xyz="-0.957539 -0.393238 0.000000" rpy="-1.870993 1.570796 0.000000" />
            <geometry>
                <mesh filename="file:///media/shantanu/Shantanu/hexapod/meshcat_sim/re/IKTRials_redone naming convention_Femur_1_vis_1.dae" />
            </geometry>
            <material name="Femur_1_material">
                <color rgba="1.000000 1.000000 1.000000 1.0" />
            </material>
        </visual>
    </link>
    <joint name="Revolute_joint_21" type="continuous">
        <axis xyz="0 0 1" />
        <parent link="Femur_1" />
        <child link="Tibia_1" />
        <origin xyz="0.228211 -0.000017 -0.000000" rpy="3.141593 3.141593 1.413717" />
    </joint>
    <link name="Tibia_1">
        <visual name="Tibia_1">
            <origin xyz="-0.846443 -0.918782 0.000000" rpy="-2.377138 1.570796 0.000000" />
            <geometry>
                <mesh filename="file:///media/shantanu/Shantanu/hexapod/meshcat_sim/re/IKTRials_redone naming convention_Tibia_1_vis_1.dae" />
            </geometry>
            <material name="Tibia_1_material">
                <color rgba="1.000000 1.000000 1.000000 1.0" />
            </material>
        </visual>
    </link>
    <joint name="Revolute_joint_02" type="continuous">
        <axis xyz="0 0 1" />
        <parent link="robot_base" />
        <child link="Coxa_2" />
        <origin xyz="-0.690000 -0.398000 0.415000" rpy="-3.141593 3.141593 0.523599" />
    </joint>
    <link name="Coxa_2">
        <visual name="Coxa_2">
            <origin xyz="-0.796558 0.000322 -0.100000" rpy="3.141593 3.141593 -0.523599" />
            <geometry>
                <mesh filename="file:///media/shantanu/Shantanu/hexapod/meshcat_sim/re/IKTRials_redone naming convention_Coxa_2_vis_1.dae" />
            </geometry>
            <material name="Coxa_2_material">
                <color rgba="1.000000 1.000000 1.000000 1.0" />
            </material>
        </visual>
    </link>
    <joint name="Revolute_joint_12" type="continuous">
        <axis xyz="0 0 1" />
        <parent link="Coxa_2" />
        <child link="Femur_2" />
        <origin xyz="0.234839 0.008753 -0.007500" rpy="-1.570796 3.539528 -3.141593" />
    </joint>
    <link name="Femur_2">
        <visual name="Femur_2">
            <origin xyz="-0.957918 -0.393356 0.008431" rpy="-1.570796 2.617994 0.300197" />
            <geometry>
                <mesh filename="file:///media/shantanu/Shantanu/hexapod/meshcat_sim/re/IKTRials_redone naming convention_Femur_2_vis_1.dae" />
            </geometry>
            <material name="Femur_2_material">
                <color rgba="1.000000 1.000000 1.000000 1.0" />
            </material>
        </visual>
    </link>
    <joint name="Revolute_joint_22" type="continuous">
        <axis xyz="0 0 1" />
        <parent link="Femur_2" />
        <child link="Tibia_2" />
        <origin xyz="0.227337 -0.000287 0.005997" rpy="-3.141593 3.141593 1.413717" />
    </joint>
    <link name="Tibia_2">
        <visual name="Tibia_2">
            <origin xyz="-0.846084 -0.918408 0.002434" rpy="-1.570796 2.617994 0.806342" />
            <geometry>
                <mesh filename="file:///media/shantanu/Shantanu/hexapod/meshcat_sim/re/IKTRials_redone naming convention_Tibia_2_vis_1.dae" />
            </geometry>
            <material name="Tibia_2_material">
                <color rgba="1.000000 1.000000 1.000000 1.0" />
            </material>
        </visual>
    </link>
    <joint name="Revolute_joint_03" type="continuous">
        <axis xyz="0 0 1" />
        <parent link="robot_base" />
        <child link="Coxa_3" />
        <origin xyz="-0.690000 0.398000 0.415000" rpy="3.141593 3.141593 -0.523599" />
    </joint>
    <link name="Coxa_3">
        <visual name="Coxa_3">
            <origin xyz="-0.690000 0.398000 -0.100000" rpy="-3.141593 3.141593 0.000000" />
            <geometry>
                <mesh filename="file:///media/shantanu/Shantanu/hexapod/meshcat_sim/re/IKTRials_redone naming convention_Coxa_3_vis_1.dae" />
            </geometry>
            <material name="Coxa_3_material">
                <color rgba="1.000000 1.000000 1.000000 1.0" />
            </material>
        </visual>
    </link>
    <joint name="Revolute_joint_13" type="continuous">
        <axis xyz="0 0 1" />
        <parent link="Coxa_3" />
        <child link="Femur_3" />
        <origin xyz="0.234000 -0.005000 -0.007500" rpy="-1.570796 3.539528 -3.141593" />
    </joint>
    <link name="Femur_3">
        <visual name="Femur_3">
            <origin xyz="-0.855324 -0.361597 -0.403000" rpy="-1.570796 3.141593 0.300197" />
            <geometry>
                <mesh filename="file:///media/shantanu/Shantanu/hexapod/meshcat_sim/re/IKTRials_redone naming convention_Femur_3_vis_1.dae" />
            </geometry>
            <material name="Femur_3_material">
                <color rgba="1.000000 1.000000 1.000000 1.0" />
            </material>
        </visual>
    </link>
    <joint name="Revolute_joint_23" type="continuous">
        <axis xyz="0 0 1" />
        <parent link="Femur_3" />
        <child link="Tibia_3" />
        <origin xyz="0.228689 0.000131 -0.003000" rpy="-3.141593 3.141593 1.413717" />
    </joint>
    <link name="Tibia_3">
        <visual name="Tibia_3">
            <origin xyz="-0.772730 -0.841915 -0.400000" rpy="-1.570796 3.141593 0.806342" />
            <geometry>
                <mesh filename="file:///media/shantanu/Shantanu/hexapod/meshcat_sim/re/IKTRials_redone naming convention_Tibia_3_vis_1.dae" />
            </geometry>
            <material name="Tibia_3_material">
                <color rgba="1.000000 1.000000 1.000000 1.0" />
            </material>
        </visual>
    </link>
    <joint name="Revolute_joint_04" type="continuous">
        <axis xyz="0 0 1" />
        <parent link="robot_base" />
        <child link="Coxa_4" />
        <origin xyz="0.000000 0.800000 0.415000" rpy="3.141593 3.141593 -1.570796" />
    </joint>
    <link name="Coxa_4">
        <visual name="Coxa_4">
            <origin xyz="-0.800000 -0.000000 -0.100000" rpy="-3.141593 3.141593 1.570796" />
            <geometry>
                <mesh filename="file:///media/shantanu/Shantanu/hexapod/meshcat_sim/re/IKTRials_redone naming convention_Coxa_4_vis_1.dae" />
            </geometry>
            <material name="Coxa_4_material">
                <color rgba="1.000000 1.000000 1.000000 1.0" />
            </material>
        </visual>
    </link>
    <joint name="Revolute_joint_14" type="continuous">
        <axis xyz="0 0 1" />
        <parent link="Coxa_4" />
        <child link="Femur_4" />
        <origin xyz="0.231500 -0.001000 -0.007500" rpy="-1.570796 3.539528 -3.141593" />
    </joint>
    <link name="Femur_4">
        <visual name="Femur_4">
            <origin xyz="-0.958017 -0.393386 -0.001000" rpy="-1.270600 -1.570796 0.000000" />
            <geometry>
                <mesh filename="file:///media/shantanu/Shantanu/hexapod/meshcat_sim/re/IKTRials_redone naming convention_Femur_4_vis_1.dae" />
            </geometry>
            <material name="Femur_4_material">
                <color rgba="1.000000 1.000000 1.000000 1.0" />
            </material>
        </visual>
    </link>
    <joint name="Revolute_joint_24" type="continuous">
        <axis xyz="0 0 1" />
        <parent link="Femur_4" />
        <child link="Tibia_4" />
        <origin xyz="0.226300 -0.000608 -0.001000" rpy="-3.141593 3.141593 1.413717" />
    </joint>
    <link name="Tibia_4">
        <visual name="Tibia_4">
            <origin xyz="-0.673204 -1.050561 -0.000000" rpy="-0.589921 -1.570796 0.000000" />
            <geometry>
                <mesh filename="file:///media/shantanu/Shantanu/hexapod/meshcat_sim/re/IKTRials_redone naming convention_Tibia_4_vis_1.dae" />
            </geometry>
            <material name="Tibia_4_material">
                <color rgba="1.000000 1.000000 1.000000 1.0" />
            </material>
        </visual>
    </link>
    <joint name="Revolute_joint_05" type="continuous">
        <axis xyz="0 0 1" />
        <parent link="robot_base" />
        <child link="Coxa_5" />
        <origin xyz="0.690000 0.400000 0.415000" rpy="-3.141593 3.141593 -2.617994" />
    </joint>
    <link name="Coxa_5">
        <visual name="Coxa_5">
            <origin xyz="-0.797558 -0.001410 -0.100000" rpy="-3.141593 3.141593 2.617994" />
            <geometry>
                <mesh filename="file:///media/shantanu/Shantanu/hexapod/meshcat_sim/re/IKTRials_redone naming convention_Coxa_5_vis_1.dae" />
            </geometry>
            <material name="Coxa_5_material">
                <color rgba="1.000000 1.000000 1.000000 1.0" />
            </material>
        </visual>
    </link>
    <joint name="Revolute_joint_15" type="continuous">
        <axis xyz="0 0 1" />
        <parent link="Coxa_5" />
        <child link="Femur_5" />
        <origin xyz="0.233808 -0.002096 -0.007000" rpy="-1.570796 3.539528 3.141593" />
    </joint>
    <link name="Femur_5">
        <visual name="Femur_5">
            <origin xyz="-0.957740 -0.393824 -0.000686" rpy="1.570796 3.665191 -2.841396" />
            <geometry>
                <mesh filename="file:///media/shantanu/Shantanu/hexapod/meshcat_sim/re/IKTRials_redone naming convention_Femur_5_vis_1.dae" />
            </geometry>
            <material name="Femur_5_material">
                <color rgba="1.000000 1.000000 1.000000 1.0" />
            </material>
        </visual>
    </link>
    <joint name="Revolute_joint_25" type="continuous">
        <axis xyz="0 0 1" />
        <parent link="Femur_5" />
        <child link="Tibia_5" />
        <origin xyz="0.227304 0.000226 -0.005253" rpy="-3.141593 3.141593 1.413717" />
    </joint>
    <link name="Tibia_5">
        <visual name="Tibia_5">
            <origin xyz="-0.845424 -0.919164 0.004567" rpy="1.570796 3.665191 -2.335251" />
            <geometry>
                <mesh filename="file:///media/shantanu/Shantanu/hexapod/meshcat_sim/re/IKTRials_redone naming convention_Tibia_5_vis_1.dae" />
            </geometry>
            <material name="Tibia_5_material">
                <color rgba="1.000000 1.000000 1.000000 1.0" />
            </material>
        </visual>
    </link>
    <joint name="Revolute_joint_06" type="continuous">
        <axis xyz="0 0 1" />
        <parent link="robot_base" />
        <child link="Coxa_6" />
        <origin xyz="0.690000 -0.400000 0.415000" rpy="-3.141593 3.141593 2.617994" />
    </joint>
    <link name="Coxa_6">
        <visual name="Coxa_6">
            <origin xyz="-0.690000 0.400000 -0.100000" rpy="-3.141593 3.141593 -3.141593" />
            <geometry>
                <mesh filename="file:///media/shantanu/Shantanu/hexapod/meshcat_sim/re/IKTRials_redone naming convention_Coxa_6_vis_1.dae" />
            </geometry>
            <material name="Coxa_6_material">
                <color rgba="1.000000 1.000000 1.000000 1.0" />
            </material>
        </visual>
    </link>
    <joint name="Revolute_joint_16" type="continuous">
        <axis xyz="0 0 1" />
        <parent link="Coxa_6" />
        <child link="Femur_6" />
        <origin xyz="0.234500 -0.000500 -0.007500" rpy="-1.570796 3.539528 3.141593" />
    </joint>
    <link name="Femur_6">
        <visual name="Femur_6">
            <origin xyz="-0.855802 -0.361745 -0.400500" rpy="1.570796 3.141593 -2.841396" />
            <geometry>
                <mesh filename="file:///media/shantanu/Shantanu/hexapod/meshcat_sim/re/IKTRials_redone naming convention_Femur_6_vis_1.dae" />
            </geometry>
            <material name="Femur_6_material">
                <color rgba="1.000000 1.000000 1.000000 1.0" />
            </material>
        </visual>
    </link>
    <joint name="Revolute_joint_26" type="continuous">
        <axis xyz="0 0 1" />
        <parent link="Femur_6" />
        <child link="Tibia_6" />
        <origin xyz="0.227551 -0.001268 -0.004000" rpy="-3.141593 3.141593 1.413717" />
    </joint>
    <link name="Tibia_6">
        <visual name="Tibia_6">
            <origin xyz="-0.615068 -0.961920 -0.396500" rpy="1.570796 3.141593 -2.160718" />
            <geometry>
                <mesh filename="file:///media/shantanu/Shantanu/hexapod/meshcat_sim/re/IKTRials_redone naming convention_Tibia_6_vis_1.dae" />
            </geometry>
            <material name="Tibia_6_material">
                <color rgba="1.000000 1.000000 1.000000 1.0" />
            </material>
        </visual>
    </link>
</robot>
