<?xml version="1.0"?>
<robot name="base_link">
    <link name="robot_base">
        <visual name="base_link">
            <origin xyz="0.275000 0.225000 0.349000" rpy="-3.141593 3.141593 -3.141593" />
            <geometry>
                <!-- <mesh filename="file:///media/shantanu/Shantanu/hexapod/meshcat_sim/hexy_urdf_v2_dae/hexy_urdf_v2_robot_base_vis_1.dae" /> -->
                <mesh filename="file://hexy_urdf_v2_dae/hexy_urdf_v2_robot_base_vis_1.dae" />
            </geometry>
            <material name="robot_base_material">
                <color rgba="0.600000 0.600000 0.600000 1.0" />
            </material>
        </visual>
        <collision>
            <origin xyz="0.275000 0.225000 0.349000" rpy="-3.141593 3.141593 -3.141593" />
            <geometry>
                <mesh filename="file://hexy_urdf_v2_4_dae/hexy_urdf_v2_4_robot_base_vis_1.dae" />
            </geometry>
        </collision>
    </link>
    <joint type="continuous" name="Revolute_joint">
        <axis xyz="0 0 1" />
        <parent link="robot_base" />
        <child link="Coxa_1" />
        <origin xyz="0.275000 -0.572000 0.449000" rpy="-3.141593 3.141593 -3.141593" />
    </joint>
    <link name="Coxa_1">
        <visual name="Coxa_1">
            <origin xyz="0.000000 0.797000 -0.100000" rpy="-3.141593 3.141593 -3.141593" />
            <geometry>
                <mesh filename="file://hexy_urdf_v2_dae/hexy_urdf_v2_Coxa_1_vis_1.dae" />
            </geometry>
            <material name="Coxa_1_material">
                <color rgba="0.500000 0.750000 0.000000 1.0" />
            </material>
        </visual>
        <collision>
            <origin xyz="0.000000 0.797000 -0.100000" rpy="-3.141593 3.141593 -3.141593" />
            <geometry>
                <mesh filename="file://hexy_urdf_v2_4_dae/hexy_urdf_v2_4_Coxa_1_vis_1.dae" />
            </geometry>
        </collision>
    </link>
    <joint type="continuous" name="Revolute_joint_7">
        <axis xyz="0 0 1" />
        <parent link="Coxa_1" />
        <child link="Femur_1" />
        <origin xyz="0.000000 -0.234000 -0.007500" rpy="-1.570796 3.141593 -1.570796" />
    </joint>
    <link name="Femur_1">
        <visual name="Femur_1">
            <origin xyz="1.031000 -0.092500 0.000000" rpy="-1.570796 -1.570796 0.000000" />
            <geometry>
                <mesh filename="file://hexy_urdf_v2_dae/hexy_urdf_v2_Femur_1_vis_1.dae" />
            </geometry>
            <material name="Femur_1_material">
                <color rgba="0.000000 0.500000 0.7500000 1.0" />
            </material>
        </visual>
        <collision>
            <origin xyz="1.031000 -0.092500 0.000000" rpy="-1.570796 -1.570796 0.000000" />
            <geometry>
                <mesh filename="file://hexy_urdf_v2_4_dae/hexy_urdf_v2_4_Femur_1_vis_1.dae" />
            </geometry>
        </collision>
    </link>
    <joint type="continuous" name="Revolute_joint_8">
        <axis xyz="0 0 1" />
        <parent link="Femur_1" />
        <child link="Tibia_1" />
        <origin xyz="-0.218000 -0.067500 -0.000000" rpy="-3.141593 3.141593 -3.141593" />
    </joint>
    <link name="Tibia_1">
        <visual name="Tibia_1">
            <origin xyz="1.249000 -0.025000 0.000000" rpy="-1.570796 -1.570796 0.000000" />
            <geometry>
                <mesh filename="file://hexy_urdf_v2_dae/hexy_urdf_v2_Tibia_1_vis_1.dae" />
            </geometry>
            <material name="Tibia_1_material">
                <color rgba="0.500000 0.000000 0.500000 1.0" />
            </material>
        </visual>
        <collision>
            <origin xyz="1.249000 -0.025000 0.000000" rpy="-1.570796 -1.570796 0.000000" />
            <geometry>
                <mesh filename="file://hexy_urdf_v2_4_dae/hexy_urdf_v2_4_Tibia_1_vis_1.dae" />
            </geometry>
        </collision>
    </link>
    <joint type="continuous" name="Revolute_joint_2">
        <axis xyz="0 0 1" />
        <parent link="robot_base" />
        <child link="Coxa_6" />
        <origin xyz="-0.415000 -0.173000 0.449000" rpy="-3.141593 3.141593 -3.141593" />
    </joint>
    <link name="Coxa_6">
        <visual name="Coxa_6">
            <origin xyz="0.690000 0.398000 -0.100000" rpy="-3.141593 3.141593 -3.141593" />
            <geometry>
                <mesh filename="file://hexy_urdf_v2_dae/hexy_urdf_v2_Coxa_6_vis_1.dae" />
            </geometry>
            <material name="Coxa_6_material">
                <color rgba="0.500000 0.750000 0.000000 1.0" />
            </material>
        </visual>
        <collision>
            <origin xyz="0.690000 0.398000 -0.100000" rpy="-3.141593 3.141593 -3.141593" />
            <geometry>
                <mesh filename="file://hexy_urdf_v2_4_dae/hexy_urdf_v2_4_Coxa_6_vis_1.dae" />
            </geometry>
        </collision>
    </link>
    <joint type="continuous" name="Revolute_joint_9">
        <axis xyz="0 0 1" />
        <parent link="Coxa_6" />
        <child link="Femur_6" />
        <origin xyz="-0.199000 -0.125000 -0.007500" rpy="-1.570796 3.141593 -2.617994" />
    </joint>
    <link name="Femur_6">
        <visual name="Femur_6">
            <origin xyz="1.031397 -0.092500 -0.008431" rpy="1.570796 3.665191 -3.141593" />
            <geometry>
                <mesh filename="file://hexy_urdf_v2_dae/hexy_urdf_v2_Femur_6_vis_1.dae" />
            </geometry>
            <material name="Femur_6_material">
                <color rgba="0.000000 0.500000 0.7500000 1.0" />
            </material>
        </visual>
        <collision>
            <origin xyz="1.031397 -0.092500 -0.008431" rpy="1.570796 3.665191 -3.141593" />
            <geometry>
                <mesh filename="file://hexy_urdf_v2_4_dae/hexy_urdf_v2_4_Femur_6_vis_1.dae" />
            </geometry>
        </collision>
    </link>
    <joint type="continuous" name="Revolute_joint_10">
        <axis xyz="0 0 1" />
        <parent link="Femur_6" />
        <child link="Tibia_6" />
        <origin xyz="-0.217086 -0.067500 -0.005997" rpy="-3.141593 3.141593 -3.141593" />
    </joint>
    <link name="Tibia_6">
        <visual name="Tibia_6">
            <origin xyz="1.248482 -0.025000 -0.002434" rpy="1.570796 3.665191 -3.141593" />
            <geometry>
                <mesh filename="file://hexy_urdf_v2_dae/hexy_urdf_v2_Tibia_6_vis_1.dae" />
            </geometry>
            <material name="Tibia_6_material">
                <color rgba="0.500000 0.000000 0.500000 1.0" />
            </material>
        </visual>
        <collision>
            <origin xyz="1.248482 -0.025000 -0.002434" rpy="1.570796 3.665191 -3.141593" />
            <geometry>
                <mesh filename="file://hexy_urdf_v2_4_dae/hexy_urdf_v2_4_Tibia_6_vis_1.dae" />
            </geometry>
        </collision>
    </link>
    <joint type="continuous" name="Revolute_joint_3">
        <axis xyz="0 0 1" />
        <parent link="robot_base" />
        <child link="Coxa_5" />
        <origin xyz="-0.415000 0.623000 0.449000" rpy="-3.141593 3.141593 -3.141593" />
    </joint>
    <link name="Coxa_5">
        <visual name="Coxa_5">
            <origin xyz="0.457150 -0.652317 -0.100000" rpy="-3.141593 3.141593 2.705260" />
            <geometry>
                <mesh filename="file://hexy_urdf_v2_dae/hexy_urdf_v2_Coxa_5_vis_1.dae" />
            </geometry>
            <material name="Coxa_5_material">
                <color rgba="0.500000 0.750000 0.000000 1.0" />
            </material>
        </visual>
        <collision>
            <origin xyz="0.457150 -0.652317 -0.100000" rpy="-3.141593 3.141593 2.705260" />
            <geometry>
                <mesh filename="file://hexy_urdf_v2_4_dae/hexy_urdf_v2_4_Coxa_5_vis_1.dae" />
            </geometry>
        </collision>
    </link>
    <joint type="continuous" name="Revolute_joint_11">
        <axis xyz="0 0 1" />
        <parent link="Coxa_5" />
        <child link="Femur_5" />
        <origin xyz="-0.209963 0.103424 -0.007500" rpy="-1.570796 3.141593 2.705260" />
    </joint>
    <link name="Femur_5">
        <visual name="Femur_5">
            <origin xyz="0.924000 -0.092500 0.403000" rpy="1.570796 3.141593 3.141593" />
            <geometry>
                <mesh filename="file://hexy_urdf_v2_dae/hexy_urdf_v2_Femur_5_vis_1.dae" />
            </geometry>
            <material name="Femur_5_material">
                <color rgba="0.000000 0.500000 0.7500000 1.0" />
            </material>
        </visual>
        <collision>
            <origin xyz="0.924000 -0.092500 0.403000" rpy="1.570796 3.141593 3.141593" />
            <geometry>
                <mesh filename="file://hexy_urdf_v2_4_dae/hexy_urdf_v2_4_Femur_5_vis_1.dae" />
            </geometry>
        </collision>
    </link>
    <joint type="continuous" name="Revolute_joint_12">
        <axis xyz="0 0 1" />
        <parent link="Femur_5" />
        <child link="Tibia_5" />
        <origin xyz="-0.218500 -0.067500 0.003000" rpy="-3.141593 3.141593 -3.141593" />
    </joint>
    <link name="Tibia_5">
        <visual name="Tibia_5">
            <origin xyz="1.142500 -0.025000 0.400000" rpy="1.570796 3.141593 3.141593" />
            <geometry>
                <mesh filename="file://hexy_urdf_v2_dae/hexy_urdf_v2_Tibia_5_vis_1.dae" />
            </geometry>
            <material name="Tibia_5_material">
                <color rgba="0.500000 0.000000 0.500000 1.0" />
            </material>
        </visual>
        <collision>
            <origin xyz="1.142500 -0.025000 0.400000" rpy="1.570796 3.141593 3.141593" />
            <geometry>
                <mesh filename="file://hexy_urdf_v2_4_dae/hexy_urdf_v2_4_Tibia_5_vis_1.dae" />
            </geometry>
        </collision>
    </link>
    <joint type="continuous" name="Revolute_joint_4">
        <axis xyz="0 0 1" />
        <parent link="robot_base" />
        <child link="Coxa_4" />
        <origin xyz="0.275000 1.025000 0.449000" rpy="-3.141593 3.141593 -3.141593" />
    </joint>
    <link name="Coxa_4">
        <visual name="Coxa_4">
            <origin xyz="0.000000 -0.800000 -0.100000" rpy="-3.141593 3.141593 -3.141593" />
            <geometry>
                <mesh filename="file://hexy_urdf_v2_dae/hexy_urdf_v2_Coxa_4_vis_1.dae" />
            </geometry>
            <material name="Coxa_4_material">
                <color rgba="0.500000 0.750000 0.000000 1.0" />
            </material>
        </visual>
        <collision>
            <origin xyz="0.000000 -0.800000 -0.100000" rpy="-3.141593 3.141593 -3.141593" />
            <geometry>
                <mesh filename="file://hexy_urdf_v2_4_dae/hexy_urdf_v2_4_Coxa_4_vis_1.dae" />
            </geometry>
        </collision>
    </link>
    <joint type="continuous" name="Revolute_joint_13">
        <axis xyz="0 0 1" />
        <parent link="Coxa_4" />
        <child link="Femur_4" />
        <origin xyz="0.001000 0.231500 -0.007500" rpy="-1.570796 3.141593 -1.570796" />
    </joint>
    <link name="Femur_4">
        <visual name="Femur_4">
            <origin xyz="-1.031500 -0.092500 -0.001000" rpy="-1.570796 -1.570796 0.000000" />
            <geometry>
                <mesh filename="file://hexy_urdf_v2_dae/hexy_urdf_v2_Femur_4_vis_1.dae" />
            </geometry>
            <material name="Femur_4_material">
                <color rgba="0.000000 0.500000 0.7500000 1.0" />
            </material>
        </visual>
        <collision>
            <origin xyz="-1.031500 -0.092500 -0.001000" rpy="-1.570796 -1.570796 0.000000" />
            <geometry>
                <mesh filename="file://hexy_urdf_v2_4_dae/hexy_urdf_v2_4_Femur_4_vis_1.dae" />
            </geometry>
        </collision>
    </link>
    <joint type="continuous" name="Revolute_joint_14">
        <axis xyz="0 0 1" />
        <parent link="Femur_4" />
        <child link="Tibia_4" />
        <origin xyz="0.216000 -0.067500 -0.001000" rpy="-3.141593 3.141593 -3.141593" />
    </joint>
    <link name="Tibia_4">
        <visual name="Tibia_4">
            <origin xyz="-1.247500 -0.025000 -0.000000" rpy="-1.570796 -1.570796 0.000000" />
            <geometry>
                <mesh filename="file://hexy_urdf_v2_dae/hexy_urdf_v2_Tibia_4_vis_1.dae" />
            </geometry>
            <material name="Tibia_4_material">
                <color rgba="0.500000 0.000000 0.500000 1.0" />
            </material>
        </visual>
        <collision>
            <origin xyz="-1.247500 -0.025000 -0.000000" rpy="-1.570796 -1.570796 0.000000" />
            <geometry>
                <mesh filename="file://hexy_urdf_v2_4_dae/hexy_urdf_v2_4_Tibia_4_vis_1.dae" />
            </geometry>
        </collision>
    </link>
    <joint type="continuous" name="Revolute_joint_5">
        <axis xyz="0 0 1" />
        <parent link="robot_base" />
        <child link="Coxa_3" />
        <origin xyz="0.965000 0.625000 0.449000" rpy="-3.141593 3.141593 -3.141593" />
    </joint>
    <link name="Coxa_3">
        <visual name="Coxa_3">
            <origin xyz="-0.690000 -0.400000 -0.100000" rpy="-3.141593 3.141593 -3.141593" />
            <geometry>
                <mesh filename="file://hexy_urdf_v2_dae/hexy_urdf_v2_Coxa_3_vis_1.dae" />
            </geometry>
            <material name="Coxa_3_material">
                <color rgba="0.500000 0.750000 0.000000 1.0" />
            </material>
        </visual>
        <collision>
            <origin xyz="-0.690000 -0.400000 -0.100000" rpy="-3.141593 3.141593 -3.141593" />
            <geometry>
                <mesh filename="file://hexy_urdf_v2_4_dae/hexy_urdf_v2_4_Coxa_3_vis_1.dae" />
            </geometry>
        </collision>
    </link>
    <joint type="continuous" name="Revolute_joint_15">
        <axis xyz="0 0 1" />
        <parent link="Coxa_3" />
        <child link="Femur_3" />
        <origin xyz="0.203531 0.115088 -0.007000" rpy="-1.570796 3.141593 -2.617994" />
    </joint>
    <link name="Femur_3">
        <visual name="Femur_3">
            <origin xyz="-1.031365 -0.093000 -0.000686" rpy="1.570796 3.665191 -3.141593" />
            <geometry>
                <mesh filename="file://hexy_urdf_v2_dae/hexy_urdf_v2_Femur_3_vis_1.dae" />
            </geometry>
            <material name="Femur_3_material">
                <color rgba="0.000000 0.500000 0.7500000 1.0" />
            </material>
        </visual>
        <collision>
            <origin xyz="-1.031365 -0.093000 -0.000686" rpy="1.570796 3.665191 -3.141593" />
            <geometry>
                <mesh filename="file://hexy_urdf_v2_4_dae/hexy_urdf_v2_4_Femur_3_vis_1.dae" />
            </geometry>
        </collision>
    </link>
    <joint type="continuous" name="Revolute_joint_16">
        <axis xyz="0 0 1" />
        <parent link="Femur_3" />
        <child link="Tibia_3" />
        <origin xyz="0.217205 -0.067000 -0.005253" rpy="-3.141593 3.141593 -3.141593" />
    </joint>
    <link name="Tibia_3">
        <visual name="Tibia_3">
            <origin xyz="-1.248570 -0.026000 0.004567" rpy="1.570796 3.665191 -3.141593" />
            <geometry>
                <mesh filename="file://hexy_urdf_v2_dae/hexy_urdf_v2_Tibia_3_vis_1.dae" />
            </geometry>
            <material name="Tibia_3_material">
                <color rgba="0.500000 0.000000 0.500000 1.0" />
            </material>
        </visual>
        <collision>
            <origin xyz="-1.248570 -0.026000 0.004567" rpy="1.570796 3.665191 -3.141593" />
            <geometry>
                <mesh filename="file://hexy_urdf_v2_4_dae/hexy_urdf_v2_4_Tibia_3_vis_1.dae" />
            </geometry>
        </collision>
    </link>
    <joint type="continuous" name="Revolute_joint_6">
        <axis xyz="0 0 1" />
        <parent link="robot_base" />
        <child link="Coxa_2" />
        <origin xyz="0.965000 -0.175000 0.449000" rpy="-3.141593 3.141593 -3.141593" />
    </joint>
    <link name="Coxa_2">
        <visual name="Coxa_2">
            <origin xyz="-0.456305 0.654130 -0.100000" rpy="-3.141593 3.141593 2.705260" />
            <geometry>
                <mesh filename="file://hexy_urdf_v2_dae/hexy_urdf_v2_Coxa_2_vis_1.dae" />
            </geometry>
            <material name="Coxa_2_material">
                <color rgba="0.500000 0.750000 0.000000 1.0" />
            </material>
        </visual>
        <collision>
            <origin xyz="-0.456305 0.654130 -0.100000" rpy="-3.141593 3.141593 2.705260" />
            <geometry>
                <mesh filename="file://hexy_urdf_v2_4_dae/hexy_urdf_v2_4_Coxa_2_vis_1.dae" />
            </geometry>
        </collision>
    </link>
    <joint type="continuous" name="Revolute_joint_17">
        <axis xyz="0 0 1" />
        <parent link="Coxa_2" />
        <child link="Femur_2" />
        <origin xyz="0.212318 -0.099557 -0.007500" rpy="-1.570796 3.141593 2.705260" />
    </joint>
    <link name="Femur_2">
        <visual name="Femur_2">
            <origin xyz="-0.924500 -0.092500 -0.400500" rpy="1.570796 3.141593 3.141593" />
            <geometry>
                <mesh filename="file://hexy_urdf_v2_dae/hexy_urdf_v2_Femur_2_vis_1.dae" />
            </geometry>
            <material name="Femur_2_material">
                <color rgba="0.000000 0.500000 0.7500000 1.0" />
            </material>
        </visual>
        <collision>
            <origin xyz="-0.924500 -0.092500 -0.400500" rpy="1.570796 3.141593 3.141593" />
            <geometry>
                <mesh filename="file://hexy_urdf_v2_4_dae/hexy_urdf_v2_4_Femur_2_vis_1.dae" />
            </geometry>
        </collision>
    </link>
    <joint type="continuous" name="Revolute_joint_18">
        <axis xyz="0 0 1" />
        <parent link="Femur_2" />
        <child link="Tibia_2" />
        <origin xyz="0.217000 -0.068500 -0.004000" rpy="-3.141593 3.141593 -3.141593" />
    </joint>
    <link name="Tibia_2">
        <visual name="Tibia_2">
            <origin xyz="-1.141500 -0.024000 -0.396500" rpy="1.570796 3.141593 3.141593" />
            <geometry>
                <mesh filename="file://hexy_urdf_v2_dae/hexy_urdf_v2_Tibia_2_vis_1.dae" />
            </geometry>
            <material name="Tibia_2_material">
                <color rgba="0.500000 0.000000 0.500000 1.0" />
            </material>
        </visual>
        <collision>
            <origin xyz="-1.141500 -0.024000 -0.396500" rpy="1.570796 3.141593 3.141593" />
            <geometry>
                <mesh filename="file://hexy_urdf_v2_4_dae/hexy_urdf_v2_4_Tibia_2_vis_1.dae" />
            </geometry>
        </collision>
    </link>
</robot>
