<?xml version="1.0" ?>
<robot name="(Unsaved)" xmlns:xacro="http://www.ros.org/wiki/xacro">

<xacro:include filename="$(find (Unsaved)_description)/urdf/materials.xacro" />
<xacro:include filename="$(find (Unsaved)_description)/urdf/(Unsaved).trans" />
<xacro:include filename="$(find (Unsaved)_description)/urdf/(Unsaved).gazebo" />
<link name="base_link">
  <inertial>
    <origin xyz="6.436791772353176e-13 8.68856977186487e-06 0.08813353689622172" rpy="0 0 0"/>
    <mass value="4.063687233537527"/>
    <inertia ixx="0.025602" iyy="0.025607" izz="0.049318" ixy="0.0" iyz="-0.0" ixz="0.0"/>
  </inertial>
  <visual>
    <origin xyz="0 0 0" rpy="0 0 0"/>
    <geometry>
      <mesh filename="package://(Unsaved)_description/meshes/base_link.stl" scale="0.001 0.001 0.001"/>
    </geometry>
    <material name="silver"/>
  </visual>
  <collision>
    <origin xyz="0 0 0" rpy="0 0 0"/>
    <geometry>
      <mesh filename="package://(Unsaved)_description/meshes/base_link.stl" scale="0.001 0.001 0.001"/>
    </geometry>
  </collision>
</link>

<link name="Coxa_6">
  <inertial>
    <origin xyz="-0.020352080722285504 -0.011750115472622377 -0.05563100010386053" rpy="0 0 0"/>
    <mass value="0.09724812532903056"/>
    <inertia ixx="2.5e-05" iyy="3e-05" izz="3.2e-05" ixy="-4e-06" iyz="0.0" ixz="0.0"/>
  </inertial>
  <visual>
    <origin xyz="0.137878 0.079604 -0.143762" rpy="0 0 0"/>
    <geometry>
      <mesh filename="package://(Unsaved)_description/meshes/Coxa_6.stl" scale="0.001 0.001 0.001"/>
    </geometry>
    <material name="silver"/>
  </visual>
  <collision>
    <origin xyz="0.137878 0.079604 -0.143762" rpy="0 0 0"/>
    <geometry>
      <mesh filename="package://(Unsaved)_description/meshes/Coxa_6.stl" scale="0.001 0.001 0.001"/>
    </geometry>
  </collision>
</link>

<link name="Coxa_1">
  <inertial>
    <origin xyz="-5.562159473445608e-08 -0.023500327284672773 -0.05563100010386053" rpy="0 0 0"/>
    <mass value="0.09724812532903056"/>
    <inertia ixx="3.2e-05" iyy="2.2e-05" izz="3.2e-05" ixy="0.0" iyz="0.0" ixz="-0.0"/>
  </inertial>
  <visual>
    <origin xyz="-0.0 0.159208 -0.143762" rpy="0 0 0"/>
    <geometry>
      <mesh filename="package://(Unsaved)_description/meshes/Coxa_1.stl" scale="0.001 0.001 0.001"/>
    </geometry>
    <material name="silver"/>
  </visual>
  <collision>
    <origin xyz="-0.0 0.159208 -0.143762" rpy="0 0 0"/>
    <geometry>
      <mesh filename="package://(Unsaved)_description/meshes/Coxa_1.stl" scale="0.001 0.001 0.001"/>
    </geometry>
  </collision>
</link>

<link name="Coxa_2">
  <inertial>
    <origin xyz="0.02350045593286834 -2.1922543673447148e-07 -0.05563100010386053" rpy="0 0 0"/>
    <mass value="0.09724812532903056"/>
    <inertia ixx="2.2e-05" iyy="3.2e-05" izz="3.2e-05" ixy="-0.0" iyz="-0.0" ixz="-0.0"/>
  </inertial>
  <visual>
    <origin xyz="-0.137878 0.079604 -0.143762" rpy="0 0 0"/>
    <geometry>
      <mesh filename="package://(Unsaved)_description/meshes/Coxa_2.stl" scale="0.001 0.001 0.001"/>
    </geometry>
    <material name="silver"/>
  </visual>
  <collision>
    <origin xyz="-0.137878 0.079604 -0.143762" rpy="0 0 0"/>
    <geometry>
      <mesh filename="package://(Unsaved)_description/meshes/Coxa_2.stl" scale="0.001 0.001 0.001"/>
    </geometry>
  </collision>
</link>

<link name="Coxa_3">
  <inertial>
    <origin xyz="0.02035208072228556 0.011750115472622377 -0.05563100010386053" rpy="0 0 0"/>
    <mass value="0.09724812532903056"/>
    <inertia ixx="2.5e-05" iyy="3e-05" izz="3.2e-05" ixy="-4e-06" iyz="-0.0" ixz="-0.0"/>
  </inertial>
  <visual>
    <origin xyz="-0.137878 -0.079604 -0.143762" rpy="0 0 0"/>
    <geometry>
      <mesh filename="package://(Unsaved)_description/meshes/Coxa_3.stl" scale="0.001 0.001 0.001"/>
    </geometry>
    <material name="silver"/>
  </visual>
  <collision>
    <origin xyz="-0.137878 -0.079604 -0.143762" rpy="0 0 0"/>
    <geometry>
      <mesh filename="package://(Unsaved)_description/meshes/Coxa_3.stl" scale="0.001 0.001 0.001"/>
    </geometry>
  </collision>
</link>

<link name="Coxa_4">
  <inertial>
    <origin xyz="5.562159475807144e-08 0.02350032728467269 -0.05563100010386053" rpy="0 0 0"/>
    <mass value="0.09724812532903056"/>
    <inertia ixx="3.2e-05" iyy="2.2e-05" izz="3.2e-05" ixy="0.0" iyz="-0.0" ixz="0.0"/>
  </inertial>
  <visual>
    <origin xyz="-0.0 -0.159208 -0.143762" rpy="0 0 0"/>
    <geometry>
      <mesh filename="package://(Unsaved)_description/meshes/Coxa_4.stl" scale="0.001 0.001 0.001"/>
    </geometry>
    <material name="silver"/>
  </visual>
  <collision>
    <origin xyz="-0.0 -0.159208 -0.143762" rpy="0 0 0"/>
    <geometry>
      <mesh filename="package://(Unsaved)_description/meshes/Coxa_4.stl" scale="0.001 0.001 0.001"/>
    </geometry>
  </collision>
</link>

<link name="Coxa_5">
  <inertial>
    <origin xyz="-0.02350045593286834 2.1922543678998263e-07 -0.05563100010386053" rpy="0 0 0"/>
    <mass value="0.09724812532903056"/>
    <inertia ixx="2.2e-05" iyy="3.2e-05" izz="3.2e-05" ixy="-0.0" iyz="0.0" ixz="0.0"/>
  </inertial>
  <visual>
    <origin xyz="0.137878 -0.079604 -0.143762" rpy="0 0 0"/>
    <geometry>
      <mesh filename="package://(Unsaved)_description/meshes/Coxa_5.stl" scale="0.001 0.001 0.001"/>
    </geometry>
    <material name="silver"/>
  </visual>
  <collision>
    <origin xyz="0.137878 -0.079604 -0.143762" rpy="0 0 0"/>
    <geometry>
      <mesh filename="package://(Unsaved)_description/meshes/Coxa_5.stl" scale="0.001 0.001 0.001"/>
    </geometry>
  </collision>
</link>

<link name="Femur_2">
  <inertial>
    <origin xyz="0.15714461044686726 -0.18487816360384196 -0.0707642936485353" rpy="0 0 0"/>
    <mass value="0.18493846398077138"/>
    <inertia ixx="2.8e-05" iyy="5e-05" izz="6e-05" ixy="0.0" iyz="-0.0" ixz="6e-06"/>
  </inertial>
  <visual>
    <origin xyz="-0.042774 -0.105274 -0.157762" rpy="0 0 0"/>
    <geometry>
      <mesh filename="package://(Unsaved)_description/meshes/Femur_2.stl" scale="0.001 0.001 0.001"/>
    </geometry>
    <material name="silver"/>
  </visual>
  <collision>
    <origin xyz="-0.042774 -0.105274 -0.157762" rpy="0 0 0"/>
    <geometry>
      <mesh filename="package://(Unsaved)_description/meshes/Femur_2.stl" scale="0.001 0.001 0.001"/>
    </geometry>
  </collision>
</link>

<link name="Femur_3">
  <inertial>
    <origin xyz="0.38891880578638915 0.009962240899335978 -0.07076429364853531" rpy="0 0 0"/>
    <mass value="0.18493846398077138"/>
    <inertia ixx="3.3e-05" iyy="4.4e-05" izz="6e-05" ixy="-1e-05" iyz="3e-06" ixz="5e-06"/>
  </inertial>
  <visual>
    <origin xyz="0.197312 -0.100662 -0.157762" rpy="0 0 0"/>
    <geometry>
      <mesh filename="package://(Unsaved)_description/meshes/Femur_3.stl" scale="0.001 0.001 0.001"/>
    </geometry>
    <material name="silver"/>
  </visual>
  <collision>
    <origin xyz="0.197312 -0.100662 -0.157762" rpy="0 0 0"/>
    <geometry>
      <mesh filename="package://(Unsaved)_description/meshes/Femur_3.stl" scale="0.001 0.001 0.001"/>
    </geometry>
  </collision>
</link>

<link name="Femur_4">
  <inertial>
    <origin xyz="0.01450000000000005 0.45745648179867177 -0.0707642936485353" rpy="0 0 0"/>
    <mass value="0.18493846398077138"/>
    <inertia ixx="5e-05" iyy="2.8e-05" izz="6e-05" ixy="-0.0" iyz="6e-06" ixz="0.0"/>
  </inertial>
  <visual>
    <origin xyz="0.0145 0.236208 -0.157762" rpy="0 0 0"/>
    <geometry>
      <mesh filename="package://(Unsaved)_description/meshes/Femur_4.stl" scale="0.001 0.001 0.001"/>
    </geometry>
    <material name="silver"/>
  </visual>
  <collision>
    <origin xyz="0.0145 0.236208 -0.157762" rpy="0 0 0"/>
    <geometry>
      <mesh filename="package://(Unsaved)_description/meshes/Femur_4.stl" scale="0.001 0.001 0.001"/>
    </geometry>
  </collision>
</link>

<link name="Femur_5">
  <inertial>
    <origin xyz="-0.3453526104468674 -0.184878836396158 -0.0707642936485353" rpy="0 0 0"/>
    <mass value="0.18493846398077138"/>
    <inertia ixx="2.8e-05" iyy="5e-05" izz="6e-05" ixy="0.0" iyz="0.0" ixz="-6e-06"/>
  </inertial>
  <visual>
    <origin xyz="-0.145434 -0.264483 -0.157762" rpy="0 0 0"/>
    <geometry>
      <mesh filename="package://(Unsaved)_description/meshes/Femur_5.stl" scale="0.001 0.001 0.001"/>
    </geometry>
    <material name="silver"/>
  </visual>
  <collision>
    <origin xyz="-0.145434 -0.264483 -0.157762" rpy="0 0 0"/>
    <geometry>
      <mesh filename="package://(Unsaved)_description/meshes/Femur_5.stl" scale="0.001 0.001 0.001"/>
    </geometry>
  </collision>
</link>

<link name="Femur_6">
  <inertial>
    <origin xyz="-0.03175580578638865 -0.2161712408993359 -0.0707642936485353" rpy="0 0 0"/>
    <mass value="0.18493846398077138"/>
    <inertia ixx="3.3e-05" iyy="4.4e-05" izz="6e-05" ixy="-1e-05" iyz="-3e-06" ixz="-5e-06"/>
  </inertial>
  <visual>
    <origin xyz="0.159851 -0.105547 -0.157762" rpy="0 0 0"/>
    <geometry>
      <mesh filename="package://(Unsaved)_description/meshes/Femur_6.stl" scale="0.001 0.001 0.001"/>
    </geometry>
    <material name="silver"/>
  </visual>
  <collision>
    <origin xyz="0.159851 -0.105547 -0.157762" rpy="0 0 0"/>
    <geometry>
      <mesh filename="package://(Unsaved)_description/meshes/Femur_6.stl" scale="0.001 0.001 0.001"/>
    </geometry>
  </collision>
</link>

<link name="Femur_1">
  <inertial>
    <origin xyz="0.014499999999999985 -0.04504048179867179 -0.0707642936485353" rpy="0 0 0"/>
    <mass value="0.18493846398077138"/>
    <inertia ixx="5e-05" iyy="2.8e-05" izz="6e-05" ixy="-0.0" iyz="-6e-06" ixz="-0.0"/>
  </inertial>
  <visual>
    <origin xyz="0.0145 0.176208 -0.157762" rpy="0 0 0"/>
    <geometry>
      <mesh filename="package://(Unsaved)_description/meshes/Femur_1.stl" scale="0.001 0.001 0.001"/>
    </geometry>
    <material name="silver"/>
  </visual>
  <collision>
    <origin xyz="0.0145 0.176208 -0.157762" rpy="0 0 0"/>
    <geometry>
      <mesh filename="package://(Unsaved)_description/meshes/Femur_1.stl" scale="0.001 0.001 0.001"/>
    </geometry>
  </collision>
</link>

<link name="Tibia_3">
  <inertial>
    <origin xyz="0.509230767163375 0.03563522060723821 -0.08593891627199479" rpy="0 0 0"/>
    <mass value="0.25344458673845177"/>
    <inertia ixx="0.000236" iyy="0.000295" izz="0.000178" ixy="-5.2e-05" iyz="7e-05" ixz="0.000122"/>
  </inertial>
  <visual>
    <origin xyz="0.269376 -0.102845 -0.144336" rpy="0 0 0"/>
    <geometry>
      <mesh filename="package://(Unsaved)_description/meshes/Tibia_3.stl" scale="0.001 0.001 0.001"/>
    </geometry>
    <material name="silver"/>
  </visual>
  <collision>
    <origin xyz="0.269376 -0.102845 -0.144336" rpy="0 0 0"/>
    <geometry>
      <mesh filename="package://(Unsaved)_description/meshes/Tibia_3.stl" scale="0.001 0.001 0.001"/>
    </geometry>
  </collision>
</link>

<link name="Tibia_4">
  <inertial>
    <origin xyz="0.01499999461414578 0.5966684318859028 -0.08593891627199479" rpy="0 0 0"/>
    <mass value="0.25344458673845177"/>
    <inertia ixx="0.000325" iyy="0.000206" izz="0.000178" ixy="0.0" iyz="0.00014" ixz="0.0"/>
  </inertial>
  <visual>
    <origin xyz="0.015 0.319708 -0.144336" rpy="0 0 0"/>
    <geometry>
      <mesh filename="package://(Unsaved)_description/meshes/Tibia_4.stl" scale="0.001 0.001 0.001"/>
    </geometry>
    <material name="silver"/>
  </visual>
  <collision>
    <origin xyz="0.015 0.319708 -0.144336" rpy="0 0 0"/>
    <geometry>
      <mesh filename="package://(Unsaved)_description/meshes/Tibia_4.stl" scale="0.001 0.001 0.001"/>
    </geometry>
  </collision>
</link>

<link name="Tibia_5">
  <inertial>
    <origin xyz="-0.4415645605340984 -0.22837884178201232 -0.08593891627199479" rpy="0 0 0"/>
    <mass value="0.25344458673845177"/>
    <inertia ixx="0.000206" iyy="0.000325" izz="0.000178" ixy="-0.0" iyz="0.0" ixz="-0.00014"/>
  </inertial>
  <visual>
    <origin xyz="-0.185934 -0.307983 -0.144336" rpy="0 0 0"/>
    <geometry>
      <mesh filename="package://(Unsaved)_description/meshes/Tibia_5.stl" scale="0.001 0.001 0.001"/>
    </geometry>
    <material name="silver"/>
  </visual>
  <collision>
    <origin xyz="-0.185934 -0.307983 -0.144336" rpy="0 0 0"/>
    <geometry>
      <mesh filename="package://(Unsaved)_description/meshes/Tibia_5.stl" scale="0.001 0.001 0.001"/>
    </geometry>
  </collision>
</link>

<link name="Tibia_6">
  <inertial>
    <origin xyz="-0.09172276716337444 -0.3113252206072381 -0.08593891627199479" rpy="0 0 0"/>
    <mass value="0.25344458673845177"/>
    <inertia ixx="0.000236" iyy="0.000295" izz="0.000178" ixy="-5.2e-05" iyz="-7e-05" ixz="-0.000122"/>
  </inertial>
  <visual>
    <origin xyz="0.148132 -0.172845 -0.144336" rpy="0 0 0"/>
    <geometry>
      <mesh filename="package://(Unsaved)_description/meshes/Tibia_6.stl" scale="0.001 0.001 0.001"/>
    </geometry>
    <material name="silver"/>
  </visual>
  <collision>
    <origin xyz="0.148132 -0.172845 -0.144336" rpy="0 0 0"/>
    <geometry>
      <mesh filename="package://(Unsaved)_description/meshes/Tibia_6.stl" scale="0.001 0.001 0.001"/>
    </geometry>
  </collision>
</link>

<link name="Tibia_1">
  <inertial>
    <origin xyz="0.015000005385854264 -0.09725243188590285 -0.08593891627199479" rpy="0 0 0"/>
    <mass value="0.25344458673845177"/>
    <inertia ixx="0.000325" iyy="0.000206" izz="0.000178" ixy="0.0" iyz="-0.00014" ixz="-0.0"/>
  </inertial>
  <visual>
    <origin xyz="0.015 0.179708 -0.144336" rpy="0 0 0"/>
    <geometry>
      <mesh filename="package://(Unsaved)_description/meshes/Tibia_1.stl" scale="0.001 0.001 0.001"/>
    </geometry>
    <material name="silver"/>
  </visual>
  <collision>
    <origin xyz="0.015 0.179708 -0.144336" rpy="0 0 0"/>
    <geometry>
      <mesh filename="package://(Unsaved)_description/meshes/Tibia_1.stl" scale="0.001 0.001 0.001"/>
    </geometry>
  </collision>
</link>

<link name="Tibia_2">
  <inertial>
    <origin xyz="0.25235656053409833 -0.2283781582179876 -0.08593891627199479" rpy="0 0 0"/>
    <mass value="0.25344458673845177"/>
    <inertia ixx="0.000206" iyy="0.000325" izz="0.000178" ixy="-0.0" iyz="-0.0" ixz="0.00014"/>
  </inertial>
  <visual>
    <origin xyz="-0.003274 -0.148774 -0.144336" rpy="0 0 0"/>
    <geometry>
      <mesh filename="package://(Unsaved)_description/meshes/Tibia_2.stl" scale="0.001 0.001 0.001"/>
    </geometry>
    <material name="silver"/>
  </visual>
  <collision>
    <origin xyz="-0.003274 -0.148774 -0.144336" rpy="0 0 0"/>
    <geometry>
      <mesh filename="package://(Unsaved)_description/meshes/Tibia_2.stl" scale="0.001 0.001 0.001"/>
    </geometry>
  </collision>
</link>

<joint name="Revolute 1" type="revolute">
  <origin xyz="-0.137878 -0.079604 0.143762" rpy="0 0 0"/>
  <parent link="base_link"/>
  <child link="Coxa_6"/>
  <axis xyz="-0.0 -0.0 1.0"/>
  <limit upper="1.570796" lower="-1.570796" effort="100" velocity="100"/>
</joint>

<joint name="Revolute 2" type="revolute">
  <origin xyz="0.0 -0.159208 0.143762" rpy="0 0 0"/>
  <parent link="base_link"/>
  <child link="Coxa_1"/>
  <axis xyz="-0.0 -0.0 1.0"/>
  <limit upper="1.570796" lower="-1.570796" effort="100" velocity="100"/>
</joint>

<joint name="Revolute 3" type="revolute">
  <origin xyz="0.137878 -0.079604 0.143762" rpy="0 0 0"/>
  <parent link="base_link"/>
  <child link="Coxa_2"/>
  <axis xyz="-0.0 -0.0 1.0"/>
  <limit upper="1.047198" lower="-0.523599" effort="100" velocity="100"/>
</joint>

<joint name="Revolute 4" type="revolute">
  <origin xyz="0.137878 0.079604 0.143762" rpy="0 0 0"/>
  <parent link="base_link"/>
  <child link="Coxa_3"/>
  <axis xyz="-0.0 -0.0 1.0"/>
  <limit upper="2.094395" lower="0.523599" effort="100" velocity="100"/>
</joint>

<joint name="Revolute 5" type="revolute">
  <origin xyz="0.0 0.159208 0.143762" rpy="0 0 0"/>
  <parent link="base_link"/>
  <child link="Coxa_4"/>
  <axis xyz="-0.0 -0.0 1.0"/>
  <limit upper="1.570796" lower="-1.570796" effort="100" velocity="100"/>
</joint>

<joint name="Revolute 6" type="revolute">
  <origin xyz="-0.137878 0.079604 0.143762" rpy="0 0 0"/>
  <parent link="base_link"/>
  <child link="Coxa_5"/>
  <axis xyz="-0.0 -0.0 1.0"/>
  <limit upper="1.047198" lower="-2.094395" effort="100" velocity="100"/>
</joint>

<joint name="Revolute 7" type="revolute">
  <origin xyz="-0.095104 0.184878 0.014" rpy="0 0 0"/>
  <parent link="Coxa_2"/>
  <child link="Femur_2"/>
  <axis xyz="0.0 -1.0 -0.0"/>
  <limit upper="0.0" lower="-2.094395" effort="100" velocity="100"/>
</joint>

<joint name="Revolute 8" type="revolute">
  <origin xyz="-0.33519 0.021058 0.014" rpy="0 0 0"/>
  <parent link="Coxa_3"/>
  <child link="Femur_3"/>
  <axis xyz="0.5 -0.866025 0.0"/>
  <limit upper="0.0" lower="-2.094395" effort="100" velocity="100"/>
</joint>

<joint name="Revolute 9" type="revolute">
  <origin xyz="-0.0145 -0.395416 0.014" rpy="0 0 0"/>
  <parent link="Coxa_4"/>
  <child link="Femur_4"/>
  <axis xyz="1.0 0.0 -0.0"/>
  <limit upper="1.570796" lower="-2.094395" effort="100" velocity="100"/>
</joint>

<joint name="Revolute 10" type="revolute">
  <origin xyz="0.283312 0.184879 0.014" rpy="0 0 0"/>
  <parent link="Coxa_5"/>
  <child link="Femur_5"/>
  <axis xyz="-0.0 1.0 -0.0"/>
  <limit upper="1.570796" lower="-2.094395" effort="100" velocity="100"/>
</joint>

<joint name="Revolute 11" type="revolute">
  <origin xyz="-0.021973 0.185151 0.014" rpy="0 0 0"/>
  <parent link="Coxa_6"/>
  <child link="Femur_6"/>
  <axis xyz="0.5 -0.866025 -0.0"/>
  <limit upper="2.094395" lower="-1.570796" effort="100" velocity="100"/>
</joint>

<joint name="Revolute 12" type="revolute">
  <origin xyz="-0.0145 -0.017 0.014" rpy="0 0 0"/>
  <parent link="Coxa_1"/>
  <child link="Femur_1"/>
  <axis xyz="-1.0 -0.0 -0.0"/>
  <limit upper="1.570796" lower="-2.094395" effort="100" velocity="100"/>
</joint>

<joint name="Revolute 13" type="revolute">
  <origin xyz="-0.072064 0.002183 -0.013426" rpy="0 0 0"/>
  <parent link="Femur_3"/>
  <child link="Tibia_3"/>
  <axis xyz="-0.5 0.866025 -0.0"/>
  <limit upper="2.094395" lower="-1.22173" effort="100" velocity="100"/>
</joint>

<joint name="Revolute 14" type="revolute">
  <origin xyz="-0.0005 -0.0835 -0.013426" rpy="0 0 0"/>
  <parent link="Femur_4"/>
  <child link="Tibia_4"/>
  <axis xyz="-1.0 0.0 -0.0"/>
  <limit upper="2.094395" lower="-1.22173" effort="100" velocity="100"/>
</joint>

<joint name="Revolute 15" type="revolute">
  <origin xyz="0.0405 0.0435 -0.013426" rpy="0 0 0"/>
  <parent link="Femur_5"/>
  <child link="Tibia_5"/>
  <axis xyz="0.0 -1.0 0.0"/>
  <limit upper="2.094395" lower="-1.22173" effort="100" velocity="100"/>
</joint>

<joint name="Revolute 16" type="revolute">
  <origin xyz="0.011719 0.067298 -0.013426" rpy="0 0 0"/>
  <parent link="Femur_6"/>
  <child link="Tibia_6"/>
  <axis xyz="0.5 -0.866025 -0.0"/>
  <limit upper="2.094395" lower="-1.22173" effort="100" velocity="100"/>
</joint>

<joint name="Revolute 17" type="revolute">
  <origin xyz="-0.0005 -0.0035 -0.013426" rpy="0 0 0"/>
  <parent link="Femur_1"/>
  <child link="Tibia_1"/>
  <axis xyz="1.0 -0.0 -0.0"/>
  <limit upper="2.094395" lower="-1.22173" effort="100" velocity="100"/>
</joint>

<joint name="Revolute 18" type="revolute">
  <origin xyz="-0.0395 0.0435 -0.013426" rpy="0 0 0"/>
  <parent link="Femur_2"/>
  <child link="Tibia_2"/>
  <axis xyz="-0.0 1.0 0.0"/>
  <limit upper="2.094395" lower="-1.22173" effort="100" velocity="100"/>
</joint>

</robot>
